Workbook

Sheet README
A1: SOG synthetic proposal archive - PoC seed data
A2: SYNTHETIC DATA. Not SOG data. Generated 1 October 2026 to seed the reference engine until the real archive is loaded.
A4: How the numbers were built
A5: 1. Construction cost per m2 comes from cited market benchmarks (sheet Benchmarks), escalated to the proposal year.
A6: 2. Fees apply SOG's own pricing logic (01.jpg): typology, service, stage, location tier, client status and site complexity.
A7: 3. Fee percentages, stage shares and modifiers are ASSUMPTIONS (sheet Assumptions) to be replaced by calibration on SOG's archive.
A8: 4. Quotes include random variation, and lost bids were priced above the model, so the engine has realistic signal to learn from.
A9: 5. Pricing_Trace shows exactly how each synthetic proposal was generated.
A11: Colour key
A12: Blue text = recorded input values (what the proposal stated). Black text = formulas calculated in this workbook.
A14: Sheets
A15: Proposals - one row per proposal (request side + response side). Totals, USD and fee per m2 are formulas.
... A19: Benchmarks - cited sources with URLs. Assumptions - parameters to calibrate. FX - exchange rates. Clients, Studios - reference.

Sheet Proposals
A1: Proposal ID | B1: Reference | C1: Title | D1: Origin | E1: Studio | F1: Client | G1: Client status | H1: Country | I1: City | J1: Location tier | K1: Typology | L1: Services | M1: Stage package | N1: GFA m2 | O1: Site area m2 | P1: Landscape m2 | Q1: Fit-out m2 | R1: Units | S1: Keys | T1: Complexity | U1: Complexity notes | V1: Submission date | W1: Currency | X1: Construction cost USD/m2 (benchmark) | Y1: Fee total (local) | Z1: Fee total (USD) | AA1: Fee per m2 GFA (USD) | AB1: Reimbursables (local) | AC1: Status | AD1: Loss reason | AE1: Project challenges | AF1: Document area unit | AG1: Stage terms used in document
A2: P01 | B2: SOG-DXB-2024-017 | C2: Marina Crest Residences - 48-storey residential tower | D2: synthetic | E2: SOG Dubai | F2: Marina Crest Developments LLC | G2: repeat | H2: UAE | I2: Dubai | J2: prime | K2: residential | L2: architecture, interior | M2: concept, schematic_design, design_development | N2: 62000 | O2: 4800 | P2: 0 | Q2: 5200 | R2: 410 | T2: medium | U2: Standard waterfront plot; marina setback rules | V2: 2024-03-12 | W2: AED | X2: 1426 | Y2: =SUMIFS(Fee_Lines!$I$2:$I$89,Fee_Lines!$A$2:$A$89,A2) -> 5725000 | Z2: =Y2/INDEX(FX!$B$2:$B$8,MATCH(W2,FX!$A$2:$A$8,0)) -> 1558883.6 | AA2: =IF(N2>0,Z2/N2,"n/a") -> 25.143284 | AB2: =SUMIFS(Reimbursables!$F$2:$F$23,Reimbursables!$A$2:$A$23,A2) -> 127000 | AC2: won | AF2: m2 | AG2: schematic_design: Schematic Design
A3: P02 | B3: SOG-DXB-2025-004 | C3: Coral Bay Resort & Spa - 220-key beachfront resort | D3: synthetic | E3: SOG Dubai | F3: Coral Bay Hospitality Holdings | G3: new | H3: UAE | I3: Ras Al Khaimah | J3: second | K3: hospitality | L3: architecture, interior, landscape | M3: concept, schematic_design, design_development, gfc_review | N3: 38000 | O3: 62000 | P3: 41000 | Q3: 21000 | S3: 220 | T3: high | U3: Sloping coastal site, coastal setback and turtle-nesting constraints | V3: 2025-02-03 | W3: AED | X3: 2778 | Y3: =SUMIFS(Fee_Lines!$I$2:$I$89,Fee_Lines!$A$2:$A$89,A3) -> 17905000 | Z3: =Y3/INDEX(FX!$B$2:$B$8,MATCH(W3,FX!$A$2:$A$8,0)) -> 4875425.5 | AA3: =IF(N3>0,Z3/N3,"n/a") -> 128.30067 | AB3: =SUMIFS(Reimbursables!$F$2:$F$23,Reimbursables!$A$2:$A$23,A3) -> 198000 | AC3: won | AF3: m2 | AG3: gfc_review: GFC Drawing Review
A4: P03 | B4: SOG-DXB-2025-021 | C4: Al Noor Gateway - mixed-use district block | D4: synthetic | E4: SOG Dubai | F4: Al Noor Urban Investment Co. | G4: new | H4: KSA | I4: Riyadh | J4: prime | K4: mixed_use | L4: architecture, landscape | M4: concept, schematic_design | N4: 145000 | O4: 38000 | P4: 16000 | Q4: 0 | R4: 520 | T4: medium | U4: Large urban block; phased delivery | V4: 2025-06-18 | W4: SAR | X4: 2670 | Y4: =SUMIFS(Fee_Lines!$I$2:$I$89,Fee_Lines!$A$2:$A$89,A4) -> 14450000 | Z4: =Y4/INDEX(FX!$B$2:$B$8,MATCH(W4,FX!$A$2:$A$8,0)) -> 3853333.3 | AA4: =IF(N4>0,Z4/N4,"n/a") -> 26.574713 | AB4: =SUMIFS(Reimbursables!$F$2:$F$23,Reimbursables!$A$2:$A$23,A4) -> 183000 | AC4: lost | AD4: Price - client selected a lower-fee competitor | AF4: m2
A5: P04 | B5: SOG-DXB-2023-031 | C5: Oasis Gardens - 120-villa community, Al Ain | D5: synthetic | E5: SOG Dubai | F5: Oasis Living Properties | G5: repeat | H5: UAE | I5: Al Ain | J5: second | K5: residential | L5: masterplan, architecture, landscape | M5: concept, schematic_design, design_development | N5: 48000 | O5: 320000 | P5: 95000 | Q5: 0 | R5: 120 | T5: low | U5: Flat greenfield site | V5: 2023-09-25 | W5: AED | X5: 1453 | Y5: =SUMIFS(Fee_Lines!$I$2:$I$89,Fee_Lines!$A$2:$A$89,A5) -> 10310000 | Z5: =Y5/INDEX(FX!$B$2:$B$8,MATCH(W5,FX!$A$2:$A$8,0)) -> 2807351.9 | AA5: =IF(N5>0,Z5/N5,"n/a") -> 58.486499 | AB5: =SUMIFS(Reimbursables!$F$2:$F$23,Reimbursables!$A$2:$A$23,A5) -> 155000 | AC5: won | AF5: m2
A6: P05 | B6: SOG-BCN-2024-006 | C6: Diagonal Norte - office refurbishment and extension | D6: synthetic | E6: SOG Barcelona | F6: Inmobiliaria Diagonal Norte S.L. | G6: new | H6: Spain | I6: Barcelona | J6: prime | K6: office | L6: architecture, interior | M6: concept, schematic_design, design_development | N6: 18500 | O6: 3100 | P6: 0 | Q6: 14000 | T6: high | U6: Protected heritage facade retained; constrained urban site | V6: 2024-05-07 | W6: EUR | X6: 1864 | Y6: =SUMIFS(Fee_Lines!$I$2:$I$89,Fee_Lines!$A$2:$A$89,A6) -> 1085000 | Z6: =Y6/INDEX(FX!$B$2:$B$8,MATCH(W6,FX!$A$2:$A$8,0)) -> 1179347.8 | AA6: =IF(N6>0,Z6/N6,"n/a") -> 63.748531 | AB6: =SUMIFS(Reimbursables!$F$2:$F$23,Reimbursables!$A$2:$A$23,A6) -> 14800 | AC6: lost | AD6: Lost to local practice with heritage track record | AF6: m2 | AG6: schematic_design: Scheme Design (Anteproyecto)
A7: P06 | B7: SOG-BCN-2025-012 | C7: Costa Luz Boutique Hotel - 85 keys, Malaga | D7: synthetic | E7: SOG Barcelona | F7: Costa Luz Hoteles S.A. | G7: repeat | H7: Spain | I7: Malaga | J7: second | K7: hospitality | L7: architecture, interior, landscape | M7: concept, schematic_design | N7: 9800 | O7: 5400 | P7: 2800 | Q7: 6500 | S7: 85 | T7: medium | U7: Historic centre height limits | V7: 2025-04-22 | W7: EUR | X7: 3274 | Y7: =SUMIFS(Fee_Lines!$I$2:$I$89,Fee_Lines!$A$2:$A$89,A7) -> 715600 | Z7: =Y7/INDEX(FX!$B$2:$B$8,MATCH(W7,FX!$A$2:$A$8,0)) -> 777826.09 | AA7: =IF(N7>0,Z7/N7,"n/a") -> 79.370009 | AB7: =SUMIFS(Reimbursables!$F$2:$F$23,Reimbursables!$A$2:$A$23,A7) -> 26250 | AC7: won | AF7: m2
A8: P07 | B8: SOG-SIN-2024-009 | C8: Straits Tower - Grade A office | D8: synthetic | E8: SOG Singapore | F8: Straits Commercial REIT | G8: new | H8: Singapore | I8: Singapore | J8: prime | K8: office | L8: architecture | M8: feasibility, concept | N8: 74000 | O8: 6200 | P8: 0 | Q8: 0 | T8: medium | U8: CBD plot; plot-ratio optimisation study | V8: 2024-08-14 | W8: SGD | X8: 2623 | Y8: =SUMIFS(Fee_Lines!$I$2:$I$89,Fee_Lines!$A$2:$A$89,A8) -> 1503000 | Z8: =Y8/INDEX(FX!$B$2:$B$8,MATCH(W8,FX!$A$2:$A$8,0)) -> 1121641.8 | AA8: =IF(N8>0,Z8/N8,"n/a") -> 15.157322 | AB8: =SUMIFS(Reimbursables!$F$2:$F$23,Reimbursables!$A$2:$A$23,A8) -> 16200 | AC8: withdrawn | AD8: Client placed project on hold | AF8: m2
A9: P08 | B9: SOG-SIN-2025-003 | C9: Harbourline Residences - condominium with clubhouse | D9: synthetic | E9: SOG Singapore | F9: Harbourline Residences Pte Ltd | G9: repeat | H9: Singapore | I9: Singapore | J9: prime | K9: residential | L9: architecture, interior, landscape | M9: concept, schematic_design, design_development, construction_review | N9: 41000 | O9: 15500 | P9: 8200 | Q9: 3800 | R9: 360 | T9: medium | U9: Waterfront; URA control plan requirements | V9: 2025-01-20 | W9: SGD | X9: 2415 | Y9: =SUMIFS(Fee_Lines!$I$2:$I$89,Fee_Lines!$A$2:$A$89,A9) -> 2822000 | Z9: =Y9/INDEX(FX!$B$2:$B$8,MATCH(W9,FX!$A$2:$A$8,0)) -> 2105970.1 | AA9: =IF(N9>0,Z9/N9,"n/a") -> 51.365126 | AB9: =SUMIFS(Reimbursables!$F$2:$F$23,Reimbursables!$A$2:$A$23,A9) -> 32400 | AC9: won | AF9: m2
A10: P09 | B10: SOG-SGN-2024-011 | C10: Saigon Riverside One - mixed-use tower (residential, hotel, retail) | D10: synthetic | E10: SOG Ho Chi Minh City | F10: Saigon Riverside Land JSC | G10: new | H10: Vietnam | I10: Ho Chi Minh City | J10: prime | K10: mixed_use | L10: architecture, interior, landscape | M10: concept, schematic_design, design_development, gfc_review | N10: 96000 | O10: 7400 | P10: 3500 | Q10: 12000 | R10: 380 | S10: 160 | T10: high | U10: Tight riverfront plot, three uses stacked, height-limit negotiation | V10: 2024-04-02 | W10: USD | X10: 965 | Y10: =SUMIFS(Fee_Lines!$I$2:$I$89,Fee_Lines!$A$2:$A$89,A10) -> 3410000 | Z10: =Y10/INDEX(FX!$B$2:$B$8,MATCH(W10,FX!$A$2:$A$8,0)) -> 3410000 | AA10: =IF(N10>0,Z10/N10,"n/a") -> 35.520833 | AB10: =SUMIFS(Reimbursables!$F$2:$F$23,Reimbursables!$A$2:$A$23,A10) -> 51000 | AC10: won | AE10: Three additional concept iterations requested; payment of DD instalment delayed four months | AF10: m2 | AG10: design_development: Basic Design / Design Development
A11: P10 | B11: SOG-SGN-2026-002 | C11: Han River Bay Resort - masterplan and 180-key resort, Da Nang | D11: synthetic | E11: SOG Ho Chi Minh City | F11: Han River Resorts JSC | G11: repeat | H11: Vietnam | I11: Da Nang | J11: second | K11: hospitality | L11: masterplan, architecture, landscape, interior | M11: concept, schematic_design | N11: 26000 | O11: 140000 | P11: 60000 | Q11: 14000 | S11: 180 | T11: medium | U11: Beachfront; flood-level considerations | V11: 2026-02-16 | W11: USD | X11: 1767 | Y11: =SUMIFS(Fee_Lines!$I$2:$I$89,Fee_Lines!$A$2:$A$89,A11) -> 1795000 | Z11: =Y11/INDEX(FX!$B$2:$B$8,MATCH(W11,FX!$A$2:$A$8,0)) -> 1795000 | AA11: =IF(N11>0,Z11/N11,"n/a") -> 69.038462 | AB11: =SUMIFS(Reimbursables!$F$2:$F$23,Reimbursables!$A$2:$A$23,A11) -> 28500 | AC11: submitted | AF11: m2
A12: P11 | B12: SOG-CAN-2023-008 | C12: Pearl Delta Tech HQ campus | D12: synthetic | E12: SOG Guangzhou | F12: Pearl Delta Technology Group | G12: new | H12: China | I12: Guangzhou | J12: prime | K12: office | L12: architecture, landscape | M12: concept, schematic_design, design_development | N12: 88000 | O12: 52000 | P12: 26000 | Q12: 0 | T12: medium | U12: Campus of four buildings with shared podium | V12: 2023-11-06 | W12: CNY | X12: 808 | Y12: =SUMIFS(Fee_Lines!$I$2:$I$89,Fee_Lines!$A$2:$A$89,A12) -> 12170000 | Z12: =Y12/INDEX(FX!$B$2:$B$8,MATCH(W12,FX!$A$2:$A$8,0)) -> 1690277.8 | AA12: =IF(N12>0,Z12/N12,"n/a") -> 19.207702 | AB12: =SUMIFS(Reimbursables!$F$2:$F$23,Reimbursables!$A$2:$A$23,A12) -> 132000 | AC12: lost | AD12: Price - local design institute bid significantly lower | AF12: m2 | AG12: design_development: Preliminary Design (DD)
A13: P12 | B13: SOG-CAN-2024-015 | C13: Foshan Riverside New District - masterplan | D13: synthetic | E13: SOG Guangzhou | F13: Foshan New District Development Co. | G13: new | H13: China | I13: Foshan | J13: second | K13: masterplan | L13: masterplan | M13: feasibility, concept | N13: 0 | O13: 1200000 | P13: 0 | Q13: 0 | T13: high | U13: River corridor, existing villages to integrate, flood management | V13: 2024-07-29 | W13: CNY | Y13: =SUMIFS(Fee_Lines!$I$2:$I$89,Fee_Lines!$A$2:$A$89,A13) -> 7130000 | Z13: =Y13/INDEX(FX!$B$2:$B$8,MATCH(W13,FX!$A$2:$A$8,0)) -> 990277.78 | AA13: =IF(N13>0,Z13/N13,"n/a") -> n/a | AB13: =SUMIFS(Reimbursables!$F$2:$F$23,Reimbursables!$A$2:$A$23,A13) -> 110000 | AC13: won | AF13: m2
A14: P13 | B14: SOG-DXB-2025-033 | C14: Arabian Sea Towers - twin residential towers, Mumbai | D14: synthetic | E14: SOG Dubai | F14: Arabian Sea Realty Pvt Ltd | G14: new | H14: India | I14: Mumbai | J14: prime | K14: residential | L14: architecture, interior | M14: concept, schematic_design, design_development | N14: 110000 | O14: 9500 | P14: 0 | Q14: 4500 | R14: 640 | T14: high | U14: Coastal regulation zone, tight plot, parking podium | V14: 2025-09-10 | W14: INR | X14: 562 | Y14: =SUMIFS(Fee_Lines!$I$2:$I$89,Fee_Lines!$A$2:$A$89,A14) -> 179700000 | Z14: =Y14/INDEX(FX!$B$2:$B$8,MATCH(W14,FX!$A$2:$A$8,0)) -> 2114117.6 | AA14: =IF(N14>0,Z14/N14,"n/a") -> 19.219251 | AB14: =SUMIFS(Reimbursables!$F$2:$F$23,Reimbursables!$A$2:$A$23,A14) -> 2500000 | AC14: lost | AD14: Fee too high relative to local market | AF14: sqft
A15: P14 | B15: SOG-DXB-2026-006 | C15: Bay Square Offices - mid-rise office building | D15: synthetic | E15: SOG Dubai | F15: Marina Crest Developments LLC | G15: repeat | H15: UAE | I15: Dubai | J15: prime | K15: office | L15: architecture, interior | M15: concept, schematic_design | N15: 27000 | O15: 3600 | P15: 0 | Q15: 9000 | T15: low | U15: Regular plot in established business district | V15: 2026-03-04 | W15: AED | X15: 1773 | Y15: =SUMIFS(Fee_Lines!$I$2:$I$89,Fee_Lines!$A$2:$A$89,A15) -> 1800000 | Z15: =Y15/INDEX(FX!$B$2:$B$8,MATCH(W15,FX!$A$2:$A$8,0)) -> 490129.34 | AA15: =IF(N15>0,Z15/N15,"n/a") -> 18.152939 | AB15: =SUMIFS(Reimbursables!$F$2:$F$23,Reimbursables!$A$2:$A$23,A15) -> 45000 | AC15: submitted | AF15: m2

Sheet Fee_Lines
A1: Proposal ID | B1: Line | C1: Service | D1: Stage | E1: Basis | F1: Basis qty | G1: Basis unit | H1: Currency | I1: Amount (local) | J1: Amount (USD)
A2: P01 | B2: 1 | C2: architecture | D2: concept | E2: pct_of_construction_cost | F2: 62000 | G2: m2 GFA | H2: AED | I2: 1590000 | J2: =I2/INDEX(FX!$B$2:$B$8,MATCH(H2,FX!$A$2:$A$8,0)) -> 432947.58
A3: P01 | B3: 2 | C3: architecture | D3: schematic_design | E3: pct_of_construction_cost | F3: 62000 | G3: m2 GFA | H3: AED | I3: 1590000 | J3: =I3/INDEX(FX!$B$2:$B$8,MATCH(H3,FX!$A$2:$A$8,0)) -> 432947.58
A4: P01 | B4: 3 | C4: architecture | D4: design_development | E4: pct_of_construction_cost | F4: 62000 | G4: m2 GFA | H4: AED | I4: 2125000 | J4: =I4/INDEX(FX!$B$2:$B$8,MATCH(H4,FX!$A$2:$A$8,0)) -> 578624.91
A5: P01 | B5: 4 | C5: interior_design | D5: concept | E5: pct_of_fitout_cost | F5: 5200 | G5: m2 fit-out | H5: AED | I5: 125000 | J5: =I5/INDEX(FX!$B$2:$B$8,MATCH(H5,FX!$A$2:$A$8,0)) -> 34036.76
A6: P01 | B6: 5 | C6: interior_design | D6: schematic_design | E6: pct_of_fitout_cost | F6: 5200 | G6: m2 fit-out | H6: AED | I6: 125000 | J6: =I6/INDEX(FX!$B$2:$B$8,MATCH(H6,FX!$A$2:$A$8,0)) -> 34036.76
A7: P01 | B7: 6 | C7: interior_design | D7: design_development | E7: pct_of_fitout_cost | F7: 5200 | G7: m2 fit-out | H7: AED | I7: 170000 | J7: =I7/INDEX(FX!$B$2:$B$8,MATCH(H7,FX!$A$2:$A$8,0)) -> 46289.993
A8: P02 | B8: 1 | C8: architecture | D8: concept | E8: pct_of_construction_cost | F8: 38000 | G8: m2 GFA | H8: AED | I8: 2935000 | J8: =I8/INDEX(FX!$B$2:$B$8,MATCH(H8,FX!$A$2:$A$8,0)) -> 799183.12
A9: P02 | B9: 2 | C9: architecture | D9: schematic_design | E9: pct_of_construction_cost | F9: 38000 | G9: m2 GFA | H9: AED | I9: 2935000 | J9: =I9/INDEX(FX!$B$2:$B$8,MATCH(H9,FX!$A$2:$A$8,0)) -> 799183.12
A10: P02 | B10: 3 | C10: architecture | D10: design_development | E10: pct_of_construction_cost | F10: 38000 | G10: m2 GFA | H10: AED | I10: 3910000 | J10: =I10/INDEX(FX!$B$2:$B$8,MATCH(H10,FX!$A$2:$A$8,0)) -> 1064669.8
A11: P02 | B11: 4 | C11: architecture | D11: gfc_review | E11: pct_of_construction_cost | F11: 38000 | G11: m2 GFA | H11: AED | I11: 980000 | J11: =I11/INDEX(FX!$B$2:$B$8,MATCH(H11,FX!$A$2:$A$8,0)) -> 266848.2
A12: P02 | B12: 5 | C12: interior_design | D12: concept | E12: pct_of_fitout_cost | F12: 21000 | G12: m2 fit-out | H12: AED | I12: 1705000 | J12: =I12/INDEX(FX!$B$2:$B$8,MATCH(H12,FX!$A$2:$A$8,0)) -> 464261.4
A13: P02 | B13: 6 | C13: interior_design | D13: schematic_design | E13: pct_of_fitout_cost | F13: 21000 | G13: m2 fit-out | H13: AED | I13: 1705000 | J13: =I13/INDEX(FX!$B$2:$B$8,MATCH(H13,FX!$A$2:$A$8,0)) -> 464261.4
... A89: P14 | B89: 4 | C89: interior_design | D89: schematic_design | E89: pct_of_fitout_cost | F89: 9000 | G89: m2 fit-out | H89: AED | I89: 165000 | J89: =I89/INDEX(FX!$B$2:$B$8,MATCH(H89,FX!$A$2:$A$8,0)) -> 44928.523

Sheet Reimbursables
A1: Proposal ID | B1: Type | C1: Qty | D1: Currency | E1: Unit rate (local) | F1: Amount (local) | G1: Note
A2: P01 | B2: renders | C2: 10 | D2: AED | E2: 7500 | F2: =C2*E2 -> 75000 | G2: Marketing-quality still images
A3: P01 | B3: site_trip | C3: 4 | D3: AED | E3: 13000 | F3: =C3*E3 -> 52000 | G3: regional trip, 2 staff, flights, hotel, per diem
A4: P02 | B4: renders | C4: 16 | D4: AED | E4: 7500 | F4: =C4*E4 -> 120000 | G4: Marketing-quality still images
A5: P02 | B5: site_trip | C5: 6 | D5: AED | E5: 13000 | F5: =C5*E5 -> 78000 | G5: regional trip, 2 staff, flights, hotel, per diem
A6: P03 | B6: renders | C6: 14 | D6: SAR | E6: 7500 | F6: =C6*E6 -> 105000 | G6: Marketing-quality still images
A7: P03 | B7: site_trip | C7: 6 | D7: SAR | E7: 13000 | F7: =C7*E7 -> 78000 | G7: regional trip, 2 staff, flights, hotel, per diem
A8: P04 | B8: renders | C8: 12 | D8: AED | E8: 7500 | F8: =C8*E8 -> 90000 | G8: Marketing-quality still images
A9: P04 | B9: site_trip | C9: 5 | D9: AED | E9: 13000 | F9: =C9*E9 -> 65000 | G9: regional trip, 2 staff, flights, hotel, per diem
A10: P05 | B10: renders | C10: 8 | D10: EUR | E10: 1850 | F10: =C10*E10 -> 14800 | G10: Marketing-quality still images
A11: P06 | B11: renders | C11: 9 | D11: EUR | E11: 1850 | F11: =C11*E11 -> 16650 | G11: Marketing-quality still images
A12: P06 | B12: site_trip | C12: 3 | D12: EUR | E12: 3200 | F12: =C12*E12 -> 9600 | G12: regional trip, 2 staff, flights, hotel, per diem
A13: P07 | B13: renders | C13: 6 | D13: SGD | E13: 2700 | F13: =C13*E13 -> 16200 | G13: Marketing-quality still images
... A23: P14 | B23: renders | C23: 6 | D23: AED | E23: 7500 | F23: =C23*E23 -> 45000 | G23: Marketing-quality still images

Sheet Payments
A1: Proposal ID | B1: Seq | C1: Milestone | D1: Share of fee | E1: Amount (local)
A2: P01 | B2: 1 | C2: Advance on signing | D2: 0.1 | E2: =D2*INDEX(Proposals!$Y$2:$Y$15,MATCH(A2,Proposals!$A$2:$A$15,0)) -> 572500
A3: P01 | B3: 2 | C3: On approval of Concept Design | D3: 0.27 | E3: =D3*INDEX(Proposals!$Y$2:$Y$15,MATCH(A3,Proposals!$A$2:$A$15,0)) -> 1545750
A4: P01 | B4: 3 | C4: On approval of Schematic Design | D4: 0.27 | E4: =D4*INDEX(Proposals!$Y$2:$Y$15,MATCH(A4,Proposals!$A$2:$A$15,0)) -> 1545750
A5: P01 | B5: 4 | C5: On approval of Design Development | D5: 0.36 | E5: =D5*INDEX(Proposals!$Y$2:$Y$15,MATCH(A5,Proposals!$A$2:$A$15,0)) -> 2061000
A6: P02 | B6: 1 | C6: Advance on signing | D6: 0.1 | E6: =D6*INDEX(Proposals!$Y$2:$Y$15,MATCH(A6,Proposals!$A$2:$A$15,0)) -> 1790500
A7: P02 | B7: 2 | C7: On approval of Concept Design | D7: 0.255 | E7: =D7*INDEX(Proposals!$Y$2:$Y$15,MATCH(A7,Proposals!$A$2:$A$15,0)) -> 4565775
A8: P02 | B8: 3 | C8: On approval of Schematic Design | D8: 0.255 | E8: =D8*INDEX(Proposals!$Y$2:$Y$15,MATCH(A8,Proposals!$A$2:$A$15,0)) -> 4565775
A9: P02 | B9: 4 | C9: On approval of Design Development | D9: 0.34 | E9: =D9*INDEX(Proposals!$Y$2:$Y$15,MATCH(A9,Proposals!$A$2:$A$15,0)) -> 6087700
A10: P02 | B10: 5 | C10: On approval of GFC Review | D10: 0.05 | E10: =D10*INDEX(Proposals!$Y$2:$Y$15,MATCH(A10,Proposals!$A$2:$A$15,0)) -> 895250
A11: P03 | B11: 1 | C11: Advance on signing | D11: 0.1 | E11: =D11*INDEX(Proposals!$Y$2:$Y$15,MATCH(A11,Proposals!$A$2:$A$15,0)) -> 1445000
A12: P03 | B12: 2 | C12: On approval of Concept Design | D12: 0.45 | E12: =D12*INDEX(Proposals!$Y$2:$Y$15,MATCH(A12,Proposals!$A$2:$A$15,0)) -> 6502500
A13: P03 | B13: 3 | C13: On approval of Schematic Design | D13: 0.45 | E13: =D13*INDEX(Proposals!$Y$2:$Y$15,MATCH(A13,Proposals!$A$2:$A$15,0)) -> 6502500
... A54: P14 | B54: 3 | C54: On approval of Schematic Design | D54: 0.45 | E54: =D54*INDEX(Proposals!$Y$2:$Y$15,MATCH(A54,Proposals!$A$2:$A$15,0)) -> 810000

Sheet Deliverables
A1: Proposal ID | B1: Item | C1: Qty
A2: P01 | B2: Design report and drawings per stage | C2: 3
A3: P01 | B3: Rendered images | C3: 10
A4: P01 | B4: Client presentations | C4: 4
A5: P02 | B5: Design report and drawings per stage | C5: 4
A6: P02 | B6: Rendered images | C6: 16
A7: P02 | B7: Client presentations | C7: 5
A8: P03 | B8: Design report and drawings per stage | C8: 2
A9: P03 | B9: Rendered images | C9: 14
A10: P03 | B10: Client presentations | C10: 3
A11: P04 | B11: Design report and drawings per stage | C11: 3
A12: P04 | B12: Rendered images | C12: 12
A13: P04 | B13: Client presentations | C13: 4
... A46: P14 | B46: Client presentations | C46: 3

Sheet TC_Deviations
A1: Proposal ID | B1: Clause | C1: Client request | D1: SOG position
A2: P02 | B2: Design rounds | C2: Unlimited revisions at concept | D2: Two rounds included per stage
A3: P03 | B3: Liability cap | C3: Uncapped liability | D3: Cap at 100% of fee
A4: P09 | B4: Liability cap | C4: Uncapped liability | D4: Cap at 100% of fee
A5: P09 | B5: Payment terms | C5: 90 days from invoice | D5: 30 days from invoice
A6: P12 | B6: Payment terms | C6: 90 days from invoice | D6: 30 days from invoice
A7: P13 | B7: Liability cap | C7: Uncapped liability | D7: Cap at 100% of fee

Sheet Pricing_Trace
A1: Proposal ID | B1: Factor | C1: Value | D1: Source | E1: Note
A2: P01 | B2: construction_cost_usd_m2 | C2: 1426.0 | D2: TT_UAE_2025 | E2: direct asset-type benchmark; escalated at 5.0% p.a. from 2025 to 2024
A3: P01 | B3: architecture_full_service_pct | C3: 3.426 | D3: assumption | E3: base 3.5% x scale x market factor 1.0
A4: P01 | B4: modifiers | C4: 0.95 | D4: assumption | E4: {"location_tier": 1.0, "client_status": 0.95, "complexity": 1.0}
A5: P01 | B5: interior_fitout_cost_usd_m2 | C5: 428 | D5: assumption | E5: 0.3 x building cost
A6: P01 | B6: quote_variation | C6: 1.004 | D6: synthetic | E6: lognormal noise
A7: P01 | B7: lost_bid_premium | C7: 1.0 | D7: synthetic | E7: applied to lost bids only
A8: P02 | B8: construction_cost_usd_m2 | C8: 2778.0 | D8: TT_UAE_2025 | E8: city average x typology ratio 1.484 (ratio from Dubai asset costs); escalated at 5.0% p.a. from 2025 to 2025
A9: P02 | B9: architecture_full_service_pct | C9: 4.625 | D9: assumption | E9: base 4.5% x scale x market factor 1.0
A10: P02 | B10: modifiers | C10: 1.03 | D10: assumption | E10: {"location_tier": 0.92, "client_status": 1.0, "complexity": 1.12}
A11: P02 | B11: interior_fitout_cost_usd_m2 | C11: 1250 | D11: assumption | E11: 0.45 x building cost
A12: P02 | B12: landscape_cost_usd_m2 | C12: 180 | D12: assumption | E12: by market cost band
... A88: P14 | B88: lost_bid_premium | C88: 1.0 | D88: synthetic | E88: applied to lost bids only

Sheet Benchmarks
A1: Market | B1: Metric | C1: Value | D1: Unit | E1: Year | F1: Source | G1: URL | H1: Note
A2: Dubai | B2: Average construction cost, 6 building types | C2: 1926 | D2: USD/m2 | E2: 2025 | F2: Turner & Townsend, UAE Market Intelligence 2025 - Construction cost performance | G2: https://marketintelligence.turnerandtownsend.com/uaemi-2025/construction-cost-performance
A3: Dubai | B3: Residential - apartments high rise | C3: 5500 | D3: AED/m2 | E3: 2025 | F3: Turner & Townsend, UAE Market Intelligence 2025 - Construction cost performance | G3: https://marketintelligence.turnerandtownsend.com/uaemi-2025/construction-cost-performance
A4: Dubai | B4: Commercial - CBD offices up to 20 floors (A-grade) | C4: 6200 | D4: AED/m2 | E4: 2025 | F4: Turner & Townsend, UAE Market Intelligence 2025 - Construction cost performance | G4: https://marketintelligence.turnerandtownsend.com/uaemi-2025/construction-cost-performance
A5: Dubai | B5: Hotels - 5 star luxury | C5: 10500 | D5: AED/m2 | E5: 2025 | F5: Turner & Townsend, UAE Market Intelligence 2025 - Construction cost performance | G5: https://marketintelligence.turnerandtownsend.com/uaemi-2025/construction-cost-performance
A6: Dubai | B6: Hotels - 3 star travellers | C6: 6500 | D6: AED/m2 | E6: 2025 | F6: Turner & Townsend, UAE Market Intelligence 2025 - Construction cost performance | G6: https://marketintelligence.turnerandtownsend.com/uaemi-2025/construction-cost-performance
A7: Dubai | B7: Construction cost inflation 2025 / 2026 | C7: 5 | D7: % p.a. | E7: 2025 | F7: Turner & Townsend, UAE Market Intelligence 2025 - Construction cost performance | G7: https://marketintelligence.turnerandtownsend.com/uaemi-2025/construction-cost-performance | H7: 4.0% forecast for 2026
A8: Abu Dhabi | B8: Average construction cost, 6 building types | C8: 1872 | D8: USD/m2 | E8: 2025 | F8: Turner & Townsend, UAE Market Intelligence 2025 - Construction cost performance | G8: https://marketintelligence.turnerandtownsend.com/uaemi-2025/construction-cost-performance
A9: Riyadh | B9: Average construction cost | C9: 3112 | D9: USD/m2 | E9: 2025 | F9: Turner & Townsend, Global Construction Market Intelligence 2025 - Middle East | G9: https://publications.turnerandtownsend.com/global-construction-market-intelligence-2025/middle-east
A10: Riyadh | B10: Residential - apartments high rise | C10: 8500 | D10: SAR/m2 | E10: 2025 | F10: Turner & Townsend, KSA Market Intelligence 2025 - Construction cost performance | G10: https://marketintelligence.turnerandtownsend.com/ksami-2025/construction-cost-performance
A11: Riyadh | B11: Commercial - CBD offices up to 20 floors (A-grade) | C11: 9000 | D11: SAR/m2 | E11: 2025 | F11: Turner & Townsend, KSA Market Intelligence 2025 - Construction cost performance | G11: https://marketintelligence.turnerandtownsend.com/ksami-2025/construction-cost-performance
A12: Riyadh | B12: Hotels - 5 star luxury | C12: 22500 | D12: SAR/m2 | E12: 2025 | F12: Turner & Townsend, KSA Market Intelligence 2025 - Construction cost performance | G12: https://marketintelligence.turnerandtownsend.com/ksami-2025/construction-cost-performance
A13: Singapore | B13: Average construction cost | C13: 3104 | D13: USD/m2 | E13: 2025 | F13: Turner & Townsend, Global Construction Market Intelligence 2025 - Asia | G13: https://publications.turnerandtownsend.com/global-construction-market-intelligence-2025/asia
A14: Ho Chi Minh City | B14: Average construction cost | C14: 1168 | D14: USD/m2 | E14: 2025 | F14: Turner & Townsend, Global Construction Market Intelligence 2025 - Asia | G14: https://publications.turnerandtownsend.com/global-construction-market-intelligence-2025/asia
A15: Hanoi | B15: Average construction cost | C15: 1147 | D15: USD/m2 | E15: 2025 | F15: Turner & Townsend, Global Construction Market Intelligence 2025 - Asia | G15: https://publications.turnerandtownsend.com/global-construction-market-intelligence-2025/asia
A16: Mumbai | B16: Average construction cost | C16: 723 | D16: USD/m2 | E16: 2025 | F16: Turner & Townsend, Global Construction Market Intelligence 2025 - Asia | G16: https://publications.turnerandtownsend.com/global-construction-market-intelligence-2025/asia
A17: China (national) | B17: Average construction cost | C17: 940 | D17: USD/m2 | E17: 2025 | F17: Turner & Townsend, China's construction market: value in the face of volatility | G17: https://www.turnerandtownsend.com/insights/chinas-construction-market-value-in-the-face-of-volatility/ | H17: Construction cost escalation ~1.0% in 2025
A18: Guangzhou | B18: Average construction cost | C18: 910 | D18: USD/m2 | E18: 2025 | F18: World Population Review, Construction Cost Index by Country 2026 (citing Turner & Townsend) | G18: https://worldpopulationreview.com/country-rankings/construction-cost-index-by-country | H18: Secondary source citing Turner & Townsend
A19: Madrid | B19: Average construction cost (proxy for Barcelona) | C19: 2206 | D19: USD/m2 | E19: 2025 | F19: World Population Review, Construction Cost Index by Country 2026 (citing Turner & Townsend) | G19: https://worldpopulationreview.com/country-rankings/construction-cost-index-by-country | H19: Secondary source citing Turner & Townsend
A20: Global | B20: Construction cost inflation forecast | C20: 3.8 | D20: % p.a. | E20: 2025 | F20: Turner & Townsend press release, GCMI 2025 | G20: https://www.turnerandtownsend.com/news/us-cities-most-expensive-places-to-build-globally/ | H20: 4.0% forecast for 2026
A21: Dubai | B21: Architectural fee range, percentage of construction cost | C21: 2-8 | D21: % | E21: 2025 | F21: Al Mujassam, Architecture Design Fees Dubai (2026) Explained | G21: https://almujassam.ae/architecture-design-fees-dubai/ | H21: Commercial projects often 2-4%
A22: Dubai | B22: Stage split: RIBA 0-3 / 4 / 5-6 | C22: 35/35/30 | D22: % of fee | E22: 2025 | F22: Real Estate Club Dubai, Architecture & Engineering Firms in Dubai 2026 (fee breakdown) | G22: https://realestateclubdubai.com/blog/property-management/best-architecture-engineering-firms-dubai-2026-compared
A23: Dubai | B23: Villa fee split: concept design | C23: 20 | D23: % of fee | E23: 2025 | F23: Al Mujassam, Architecture Design Fees Dubai (2026) Explained | G23: https://almujassam.ae/architecture-design-fees-dubai/
A24: Dubai | B24: Interior design fee, luxury studios | C24: 10-20 | D24: % of fit-out cost | E24: 2025 | F24: Kat Black Design Studio, Interior design cost in Dubai 2026 | G24: https://katblackuae.com/insights/how-much-does-interior-design-cost-in-dubai-2026-complete-guide/
A25: Global | B25: Landscape design fee, multi-family / mixed-use | C25: 7-12 | D25: % of landscape construction | E25: 2025 | F25: Place Landscape Architecture, Landscape architect cost guide 2026 | G25: https://www.place-la.com/post/how-much-does-a-landscape-architect-cost-a-pacific-northwest-pricing-guide-for-2026

Sheet Assumptions
A1: Parameter | B1: Value | C1: Unit | D1: Rationale
A2: full_service_fee_pct.residential_highrise | B2: 3.5 | C2: % of construction cost | D2: Within cited Dubai 2-8% range; large commercial-scale projects sit at the low end
A3: full_service_fee_pct.residential_villa | B3: 6 | C3: % of construction cost | D3: Cited villa range 5-8%
A4: full_service_fee_pct.office | B4: 3 | C4: % of construction cost | D4: Cited commercial 2-4%
A5: full_service_fee_pct.mixed_use | B5: 3.5 | C5: % of construction cost | D5: Between residential and office
A6: full_service_fee_pct.hospitality | B6: 4.5 | C6: % of construction cost | D6: Higher design intensity than residential
A7: scale_exponent | B7: -0.1 | C7: fee % x (GFA/50,000)^exp | D7: Fee % falls as projects grow
A8: market_pct_factor.UAE | B8: 1 | C8: multiplier | D8: Reference market
A9: market_pct_factor.KSA | B9: 1 | C9: multiplier
A10: market_pct_factor.Spain | B10: 1.1 | C10: multiplier | D10: European design fees typically a higher % of cost
A11: market_pct_factor.Singapore | B11: 1 | C11: multiplier
A12: market_pct_factor.Vietnam | B12: 1.5 | C12: multiplier | D12: International design-led firm premium in low construction-cost markets
A13: market_pct_factor.China | B13: 1.45 | C13: multiplier | D13: As above
A14: market_pct_factor.India | B14: 1.55 | C14: multiplier | D14: As above
A15: stage_share.feasibility | B15: 0.05 | C15: share of full-service fee | D15: Informed by cited RIBA 0-3 = 35% split
A16: stage_share.concept | B16: 0.15 | C16: share of full-service fee | D16: Cited villa concept 15-20%
A17: stage_share.schematic_design | B17: 0.15 | C17: share of full-service fee
A18: stage_share.design_development | B18: 0.2 | C18: share of full-service fee
A19: stage_share.gfc_review | B19: 0.05 | C19: share of full-service fee | D19: Review of local architect-of-record GFC drawings
A20: stage_share.construction_review | B20: 0.08 | C20: share of full-service fee | D20: Periodic design-intent reviews, not supervision
A21: modifier.location_tier.second | B21: 0.92 | C21: multiplier | D21: SOG 01.jpg: prime vs second-tier city
A22: modifier.client.repeat | B22: 0.95 | C22: multiplier | D22: SOG 01.jpg: customer status
A23: modifier.complexity.low | B23: 0.95 | C23: multiplier | D23: SOG 01.jpg: site complexity
A24: modifier.complexity.high | B24: 1.12 | C24: multiplier
A25: interior.fitout_cost_ratio.hospitality | B25: 0.45 | C25: of building cost/m2 | D25: FF&E and fit-out share
A26: interior.fitout_cost_ratio.residential | B26: 0.3 | C26: of building cost/m2 | D26: Amenities and show units
A27: interior.fitout_cost_ratio.office | B27: 0.2 | C27: of building cost/m2 | D27: Cat B fit-out
A28: interior.fee_pct | B28: 9 | C28: % of fit-out cost | D28: Below cited luxury studio 10-20%, as large-scale work
A29: interior.stage_share_to_dd | B29: 0.6 | C29: share of interior fee | D29: Concept + SD + DD
A30: landscape.cost_per_m2.high_cost | B30: 180 | C30: USD/m2 | D30: UAE, KSA, Singapore, Spain
A31: landscape.cost_per_m2.low_cost | B31: 90 | C31: USD/m2 | D31: Vietnam, China, India
A32: landscape.fee_pct | B32: 9 | C32: % of landscape construction | D32: Cited 7-12% for multi-family / mixed-use
A33: landscape.stage_share_to_dd | B33: 0.55 | C33: share of landscape fee
A34: masterplan.rate_per_ha | B34: 14000 | C34: USD/ha (first 50 ha) | D34: No reliable public benchmark found; calibrate with SOG
A35: masterplan.rate_per_ha_above_50 | B35: 7000 | C35: USD/ha (above 50 ha)
A36: render.unit_price.high_cost | B36: 2000 | C36: USD per render
A37: render.unit_price.low_cost | B37: 1500 | C37: USD per render
A38: trip.regional | B38: 3500 | C38: USD per trip | D38: Flights, hotel, per diem, 2 staff
A39: trip.long_haul | B39: 6000 | C39: USD per trip
A40: quote_variation | B40: lognormal sd 0.06 | D40: Real quotes vary around the model
...

Sheet Clients
A1: Client ID | B1: Name (fictitious) | C1: Type | D1: Country
A2: C01 | B2: Marina Crest Developments LLC | C2: Private developer | D2: UAE
A3: C02 | B3: Coral Bay Hospitality Holdings | C3: Hotel owner | D3: UAE
A4: C03 | B4: Al Noor Urban Investment Co. | C4: Private developer | D4: KSA
A5: C04 | B5: Oasis Living Properties | C5: Private developer | D5: UAE
A6: C05 | B6: Inmobiliaria Diagonal Norte S.L. | C6: Investor | D6: Spain
A7: C06 | B7: Costa Luz Hoteles S.A. | C7: Hotel owner | D7: Spain
A8: C07 | B8: Straits Commercial REIT | C8: REIT | D8: Singapore
A9: C08 | B9: Harbourline Residences Pte Ltd | C9: Private developer | D9: Singapore
A10: C09 | B10: Saigon Riverside Land JSC | C10: Private developer | D10: Vietnam
A11: C10 | B11: Han River Resorts JSC | C11: Hotel owner | D11: Vietnam
A12: C11 | B12: Pearl Delta Technology Group | C12: Corporate occupier | D12: China
... A14: C13 | B14: Arabian Sea Realty Pvt Ltd | C14: Private developer | D14: India

Sheet Studios
A1: Code | B1: Studio | C1: City | D1: Country
A2: DXB | B2: SOG Dubai | C2: Dubai | D2: UAE
A3: BCN | B3: SOG Barcelona | C3: Barcelona | D3: Spain
A4: SIN | B4: SOG Singapore | C4: Singapore | D4: Singapore
A5: SGN | B5: SOG Ho Chi Minh City | C5: Ho Chi Minh City | D5: Vietnam
A6: CAN | B6: SOG Guangzhou | C6: Guangzhou | D6: China

Sheet FX
A1: Currency | B1: Units per USD | C1: Note
A2: USD | B2: 1 | C2: Base currency
A3: AED | B3: 3.6725 | C3: Official USD peg
A4: SAR | B4: 3.75 | C4: Official USD peg
A5: EUR | B5: 0.92 | C5: Illustrative rate - replace with dated rates
A6: SGD | B6: 1.34 | C6: Illustrative rate - replace with dated rates
A7: CNY | B7: 7.2 | C7: Illustrative rate - replace with dated rates
A8: INR | B8: 85 | C8: Illustrative rate - replace with dated rates
